<?xml version="1.0"?>
<robot name="myfirst">
    <link name="base_link">
      <visual>
        <geometry>
          <box size="0.1 0.24 0.1"/>
        </geometry>
      </visual>
    </link>

    <link name="right_rear_wheel">
      <visual>
        <geometry>
          <cylinder length ="0.06" radius="0.06"/>
        </geometry>
        <origin rpy="0 1.57075 0"/>
      </visual>
    </link>

    <joint name="base_to_right_rear_wheel" type="continuous">
      <parent link="base_link"/>
      <child link="right_rear_wheel"/>
      <origin xyz="0.12 -0.12 -0.05"/>
    </joint>

    <link name="left_rear_wheel">
      <visual>
        <geometry>
          <cylinder length ="0.06" radius="0.06"/>
        </geometry>
        <origin rpy="0 -1.57075 0"/>
      </visual>
    </link>
 
    <joint name="base_to_left_rear_wheel" type="continuous">
      <parent link="base_link"/>
      <child link="left_rear_wheel"/>
      <origin xyz="-0.12 -0.12 -0.05"/>
    </joint>









    <link name="right_front_wheel">
      <visual>
        <geometry>
          <cylinder length ="0.06" radius="0.06"/>
        </geometry>
        <origin rpy="0 1.57075 0"/>
      </visual>
    </link>
 
    <joint name="base_to_right_front_wheel" type="continuous">
      <parent link="base_link"/>
      <child link="right_front_wheel"/>
      <origin xyz="0.12 0.12 -0.05"/>
    </joint>

    <link name="left_front_wheel">
      <visual>
        <geometry>
          <cylinder length ="0.06" radius="0.06"/>
        </geometry>
        <origin rpy="0 -1.57075 0"/>
      </visual>
    </link>
 
    <joint name="base_to_left_front_wheel" type="continuous">
      <parent link="base_link"/>
      <child link="left_front_wheel"/>
      <origin xyz="-0.12 0.12 -0.05"/>
    </joint>

</robot>
