<!--  --><?xml version="1.0" ?>
<!-- =================================================================================== -->
<!-- |    This document was autogenerated by xacro from rc-car-model.xacro             | -->
<!-- |    EDITING THIS FILE BY HAND IS NOT RECOMMENDED                                 | -->
<!-- =================================================================================== -->
<!-- A simple model of the rc-car for rviz -->
<!-- urdf-viz for quick viewing-->
<robot name="rc-car" xmlns:xacro="http://www.ros.org/wiki/xacro">
  <material name="black">
    <color rgba="0.2 0.2 0.2 1"/>
  </material>
  <material name="blue">
    <color rgba="0.3 0.57 1. 1"/>
  </material>
  


  ### base link
  
  <link name="base_link">
    <visual>
      <origin xyz="0.111 0 0.125"/>
      <geometry>
        <box size="0.222 0.1 0.11"/>
      </geometry>
      <material name="blue"/>
    </visual>
  </link>
  

  ### laser
  
  <joint name="base_to_laser_model" type="fixed">
    <parent link="base_link"/>
    <child link="laser_model"/>
    <origin xyz="0.275 0 0.205"/>
  </joint>
  <link name="laser_model">
    <visual>
      <geometry>
        <cylinder length="0.05" radius="0.026"/>
      </geometry>
      <material name="black"/>
    </visual>
  </link>
  

  ### Back left wheel
  
  <joint name="base_to_back_left_wheel" type="continuous">
    <parent link="base_link"/>
    <child link="back_left_wheel"/>
    <origin xyz="0 0.1025 0.06"/>
    <axis xyz="0 1 0"/>
  </joint>
  <link name="back_left_wheel">
    <visual>
      <geometry>
        <cylinder length="0.055" radius="0.06"/>
      </geometry>
      <material name="black"/>
      <origin rpy="1.57079632679 0 0"/>
    </visual>
  </link>
  

  ### Back right wheel
  
  <joint name="base_to_back_right_wheel" type="continuous">
    <parent link="base_link"/>
    <child link="back_right_wheel"/>
    <origin xyz="0 -0.1025 0.06"/>
    <axis xyz="0 1 0"/>
  </joint>
  <link name="back_right_wheel">
    <visual>
      <geometry>
        <cylinder length="0.055" radius="0.06"/>
      </geometry>
      <material name="black"/>
      <origin rpy="1.57079632679 0 0"/>
    </visual>
  </link>
  

  ### Front right wheel
  
  <joint name="base_to_front_left_hinge" type="continuous">
    <parent link="base_link"/>
    <child link="front_left_hinge"/>
    <origin xyz="0.222 0.1025 0.06"/>
    <axis xyz="0 0 1"/>
  </joint>
  <link name="front_left_hinge"/>
  <joint name="front_left_hinge_to_wheel" type="continuous">
    <parent link="front_left_hinge"/>
    <child link="front_left_wheel"/>
    <axis xyz="0 1 0"/>
    <orign xyz="0 0.0275 0"/>
  </joint>
  <link name="front_left_wheel">
    <visual>
      <geometry>
        <cylinder length="0.055" radius="0.06"/>
      </geometry>
      <material name="black"/>
      <origin rpy="1.57079632679 0 0"/>
    </visual>
  </link>
  

  ### Front left wheel
  
  <joint name="base_to_front_right_hinge" type="continuous">
    <parent link="base_link"/>
    <child link="front_right_hinge"/>
    <origin xyz="0.222 -0.075 0.06"/>
    <axis xyz="0 0 1"/>
  </joint>
  <link name="front_right_hinge"/>
  <joint name="front_right_hinge_to_wheel" type="continuous">
    <parent link="front_right_hinge"/>
    <child link="front_right_wheel"/>
    <axis xyz="0 1 0"/>
    <origin xyz="0 -0.0275 0"/>
  </joint>
  <link name="front_right_wheel">
    <visual>
      <geometry>
        <cylinder length="0.055" radius="0.06"/>
      </geometry>
      <material name="black"/>
      <origin rpy="1.57079632679 0 0"/>
    </visual>
  </link>

  ### sensor simulation
  <gazebo>
    <plugin name="imu_plugin" filename="libgazebo_ros_imu.so">
      <alwaysOn>true</alwaysOn>
      <bodyName>imu_sensor</bodyName>
      <topicName>/imu/data</topicName>
      <serviceName>imu_service</serviceName>
      <gaussianNoise>0.0</gaussianNoise>
      <updateRate>20.0</updateRate>
    </plugin>

    <plugin name="gazebo_ros_gps" filename="libhector_gazebo_ros_gps.so">
        <updateRate>4.0</updateRate>
        <bodyName>gps_sensor</bodyName>
        <frameId>gps_sensor</frameId>
        <topicName>/gps/fix</topicName>
        <velocityTopicName>/gps/fix_velocity</velocityTopicName>
        <referenceLatitude>39.78020</referenceLatitude>
        <referenceLongitude>-86.16289</referenceLongitude>
        <referenceHeading>90</referenceHeading>
        <referenceAltitude>10</referenceAltitude>
        <offset>0 0 0</offset>
        <drift>0.001 0.001 0.001</drift>
        <gaussianNoise>5.0 5.0 5.0</gaussianNoise>
        <velocityDrift>0.001 0.001 0.001</velocityDrift>
        <velocityGaussianNoise>0.5 0.5 0.5</velocityGaussianNoise>
<!--                <drift>0.001 0.001 0.001</drift>-->
<!--                <gaussianNoise>0.01 0.01 0.01</gaussianNoise>-->
<!--                <velocityDrift>0 0 0</velocityDrift>-->
<!--                <velocityGaussianNoise>0.05 0.05 0.05</velocityGaussianNoise>-->
    </plugin>
  </gazebo>



</robot>


